Workbook

Sheet 01.06
A1: Matricula | B1: Nome docente | C1: Data de Admissão | D1: CH total de contrato | E1: Horas a alocar | F1: Campus | G1: Curso | H1: Gera agenda | I1: Status 01/06 | J1: Status 02/06 | K1: Status 03/06 | L1: Status 04/06 | M1: Status 05/06 | N1: Resultado Agenda | O1: Resultado TACH
A2: 8306 | B2: ADALBERTO CARAMORI PETRY | C2: 02/05/2001 | D2: 2 | E2: 2 | F2: CAMPUS CURITIBA | G2: 4093 - DIREITO - ADM - CTBA (GRADUAÇÃO PRESENCIAL) | H2: SIM | I2: NÃO CRIADO | J2: NÃO CRIADO | K2: NÃO CRIADO | L2: FERIADO | M2: FERIADO | N2: =IF(AND(H2="SIM",E2>0),"Pendência de Agenda",IF(AND(H2="NÃO",E2=0),"Sem Pendência",IF(AND(H2="Sim",E2=0),"Sem Pendência",""))) -> Pendência de Agenda | O2: =IF(AND(D2>0,J2="Finalizado"),"Pendência de TACH",IF(AND(D2>0,J2="Não Criado"),"Pendência de TACH",IF(AND(D2>0,J2="Rascunho"),"Pendência de TACH",IF(AND(D2>0,J2="NECESSÁRIO AJUSTAR"),"Pendência de TACH",IF(AND(D2>0,J2="Aguardando Aprovação"),"Sem Pendência de TACH",IF(AND(D2>0,J2="Aprovado"),"Sem Pendência de TACH",IF(AND(D2>0,K2="Finalizado"),"Pendência de TACH",IF(AND(D2>0,K2="Não Criado"),"Pendência de TACH",IF(AND(D2>0,K2="Rascunho"),"Pendência de TACH",IF(AND(D2>0,K2="NECESSÁRIO AJUSTAR"),"Pendência de TACH",IF(AND(D2>0,K2="Aguardando Aprovação"),"Sem Pendência de TACH",IF(AND(D2>0,K2="Aprovado"),"Sem Pendência de TACH",IF(AND(D2>0,K2="Finalizado"),"Pendência de TACH",IF(AND(D2>0,K2="Não Criado"),"Pendência de TACH",IF(AND(D2>0,K2="Rascunho"),"Pendência de TACH"))))))))))))))) -> Pendência de TACH
A3: 90013836 | B3: ANA LUIZA CHALUSNHAK | C3: 23/02/2026 | D3: 2 | E3: 2 | F3: CAMPUS CURITIBA | G3: 4093 - DIREITO - ADM - CTBA (GRADUAÇÃO PRESENCIAL) | H3: SIM | I3: FINALIZADO | J3: FINALIZADO | K3: FINALIZADO | L3: FERIADO | M3: FERIADO | N3: =IF(AND(H3="SIM",E3>0),"Pendência de Agenda",IF(AND(H3="NÃO",E3=0),"Sem Pendência",IF(AND(H3="Sim",E3=0),"Sem Pendência",""))) -> Pendência de Agenda | O3: =IF(AND(D3>0,J3="Finalizado"),"Pendência de TACH",IF(AND(D3>0,J3="Não Criado"),"Pendência de TACH",IF(AND(D3>0,J3="Rascunho"),"Pendência de TACH",IF(AND(D3>0,J3="NECESSÁRIO AJUSTAR"),"Pendência de TACH",IF(AND(D3>0,J3="Aguardando Aprovação"),"Sem Pendência de TACH",IF(AND(D3>0,J3="Aprovado"),"Sem Pendência de TACH",IF(AND(D3>0,K3="Finalizado"),"Pendência de TACH",IF(AND(D3>0,K3="Não Criado"),"Pendência de TACH",IF(AND(D3>0,K3="Rascunho"),"Pendência de TACH",IF(AND(D3>0,K3="NECESSÁRIO AJUSTAR"),"Pendência de TACH",IF(AND(D3>0,K3="Aguardando Aprovação"),"Sem Pendência de TACH",IF(AND(D3>0,K3="Aprovado"),"Sem Pendência de TACH",IF(AND(D3>0,K3="Finalizado"),"Pendência de TACH",IF(AND(D3>0,K3="Não Criado"),"Pendência de TACH",IF(AND(D3>0,K3="Rascunho"),"Pendência de TACH"))))))))))))))) -> Pendência de TACH
A4: 90009703 | B4: ANDERSON NITSCHE | C4: 01/03/2023 | D4: 18 | E4: 18 | F4: CAMPUS CURITIBA | G4: 3541 - MEDICINA - ADM - CTBA (GRADUAÇÃO PRESENCIAL) | H4: SIM | I4: RASCUNHO | J4: RASCUNHO | K4: RASCUNHO | L4: FERIADO | M4: FERIADO | N4: =IF(AND(H4="SIM",E4>0),"Pendência de Agenda",IF(AND(H4="NÃO",E4=0),"Sem Pendência",IF(AND(H4="Sim",E4=0),"Sem Pendência",""))) -> Pendência de Agenda | O4: =IF(AND(D4>0,J4="Finalizado"),"Pendência de TACH",IF(AND(D4>0,J4="Não Criado"),"Pendência de TACH",IF(AND(D4>0,J4="Rascunho"),"Pendência de TACH",IF(AND(D4>0,J4="NECESSÁRIO AJUSTAR"),"Pendência de TACH",IF(AND(D4>0,J4="Aguardando Aprovação"),"Sem Pendência de TACH",IF(AND(D4>0,J4="Aprovado"),"Sem Pendência de TACH",IF(AND(D4>0,K4="Finalizado"),"Pendência de TACH",IF(AND(D4>0,K4="Não Criado"),"Pendência de TACH",IF(AND(D4>0,K4="Rascunho"),"Pendência de TACH",IF(AND(D4>0,K4="NECESSÁRIO AJUSTAR"),"Pendência de TACH",IF(AND(D4>0,K4="Aguardando Aprovação"),"Sem Pendência de TACH",IF(AND(D4>0,K4="Aprovado"),"Sem Pendência de TACH",IF(AND(D4>0,K4="Finalizado"),"Pendência de TACH",IF(AND(D4>0,K4="Não Criado"),"Pendência de TACH",IF(AND(D4>0,K4="Rascunho"),"Pendência de TACH"))))))))))))))) -> Pendência de TACH
A5: 90014229 | B5: ANDRE LUIZ DE SOUZA PAULA | C5: 11/05/2026 | D5: 6 | E5: 6 | F5: CAMPUS CURITIBA | G5: 1031412 - CIBERSEGURANÇA - ADM - CTBA (GRADUAÇÃO PRESENCIAL) | H5: SIM | I5: NÃO CRIADO | J5: NÃO CRIADO | K5: NÃO CRIADO | L5: FERIADO | M5: FERIADO | N5: =IF(AND(H5="SIM",E5>0),"Pendência de Agenda",IF(AND(H5="NÃO",E5=0),"Sem Pendência",IF(AND(H5="Sim",E5=0),"Sem Pendência",""))) -> Pendência de Agenda | O5: =IF(AND(D5>0,J5="Finalizado"),"Pendência de TACH",IF(AND(D5>0,J5="Não Criado"),"Pendência de TACH",IF(AND(D5>0,J5="Rascunho"),"Pendência de TACH",IF(AND(D5>0,J5="NECESSÁRIO AJUSTAR"),"Pendência de TACH",IF(AND(D5>0,J5="Aguardando Aprovação"),"Sem Pendência de TACH",IF(AND(D5>0,J5="Aprovado"),"Sem Pendência de TACH",IF(AND(D5>0,K5="Finalizado"),"Pendência de TACH",IF(AND(D5>0,K5="Não Criado"),"Pendência de TACH",IF(AND(D5>0,K5="Rascunho"),"Pendência de TACH",IF(AND(D5>0,K5="NECESSÁRIO AJUSTAR"),"Pendência de TACH",IF(AND(D5>0,K5="Aguardando Aprovação"),"Sem Pendência de TACH",IF(AND(D5>0,K5="Aprovado"),"Sem Pendência de TACH",IF(AND(D5>0,K5="Finalizado"),"Pendência de TACH",IF(AND(D5>0,K5="Não Criado"),"Pendência de TACH",IF(AND(D5>0,K5="Rascunho"),"Pendência de TACH"))))))))))))))) -> Pendência de TACH
A6: 90005226 | B6: CESAR RIBEIRO ZUCCOLI | C6: 01/04/2019 | D6: 14 | E6: 14 | F6: CAMPUS LONDRINA | G6: 105237 - MEDICINA - ADM - LDN (GRADUAÇÃO PRESENCIAL) | H6: SIM | I6: APROVADO | J6: APROVADO | K6: APROVADO | L6: FERIADO | M6: FERIADO | N6: =IF(AND(H6="SIM",E6>0),"Pendência de Agenda",IF(AND(H6="NÃO",E6=0),"Sem Pendência",IF(AND(H6="Sim",E6=0),"Sem Pendência",""))) -> Pendência de Agenda | O6: =IF(AND(D6>0,J6="Finalizado"),"Pendência de TACH",IF(AND(D6>0,J6="Não Criado"),"Pendência de TACH",IF(AND(D6>0,J6="Rascunho"),"Pendência de TACH",IF(AND(D6>0,J6="NECESSÁRIO AJUSTAR"),"Pendência de TACH",IF(AND(D6>0,J6="Aguardando Aprovação"),"Sem Pendência de TACH",IF(AND(D6>0,J6="Aprovado"),"Sem Pendência de TACH",IF(AND(D6>0,K6="Finalizado"),"Pendência de TACH",IF(AND(D6>0,K6="Não Criado"),"Pendência de TACH",IF(AND(D6>0,K6="Rascunho"),"Pendência de TACH",IF(AND(D6>0,K6="NECESSÁRIO AJUSTAR"),"Pendência de TACH",IF(AND(D6>0,K6="Aguardando Aprovação"),"Sem Pendência de TACH",IF(AND(D6>0,K6="Aprovado"),"Sem Pendência de TACH",IF(AND(D6>0,K6="Finalizado"),"Pendência de TACH",IF(AND(D6>0,K6="Não Criado"),"Pendência de TACH",IF(AND(D6>0,K6="Rascunho"),"Pendência de TACH"))))))))))))))) -> Sem Pendência de TACH
A7: 19800 | B7: CLAUDIA MARIA BORGES COSTA PINTO | C7: 03/03/2009 | D7: 7 | E7: 7 | F7: CAMPUS CURITIBA | G7: 4093 - DIREITO - ADM - CTBA (GRADUAÇÃO PRESENCIAL) | H7: SIM | I7: AGUARDANDO APROVAÇÃO | J7: AGUARDANDO APROVAÇÃO | K7: AGUARDANDO APROVAÇÃO | L7: FERIADO | M7: FERIADO | N7: =IF(AND(H7="SIM",E7>0),"Pendência de Agenda",IF(AND(H7="NÃO",E7=0),"Sem Pendência",IF(AND(H7="Sim",E7=0),"Sem Pendência",""))) -> Pendência de Agenda | O7: =IF(AND(D7>0,J7="Finalizado"),"Pendência de TACH",IF(AND(D7>0,J7="Não Criado"),"Pendência de TACH",IF(AND(D7>0,J7="Rascunho"),"Pendência de TACH",IF(AND(D7>0,J7="NECESSÁRIO AJUSTAR"),"Pendência de TACH",IF(AND(D7>0,J7="Aguardando Aprovação"),"Sem Pendência de TACH",IF(AND(D7>0,J7="Aprovado"),"Sem Pendência de TACH",IF(AND(D7>0,K7="Finalizado"),"Pendência de TACH",IF(AND(D7>0,K7="Não Criado"),"Pendência de TACH",IF(AND(D7>0,K7="Rascunho"),"Pendência de TACH",IF(AND(D7>0,K7="NECESSÁRIO AJUSTAR"),"Pendência de TACH",IF(AND(D7>0,K7="Aguardando Aprovação"),"Sem Pendência de TACH",IF(AND(D7>0,K7="Aprovado"),"Sem Pendência de TACH",IF(AND(D7>0,K7="Finalizado"),"Pendência de TACH",IF(AND(D7>0,K7="Não Criado"),"Pendência de TACH",IF(AND(D7>0,K7="Rascunho"),"Pendência de TACH"))))))))))))))) -> Sem Pendência de TACH
A8: 90013955 | B8: EMILE FERNANDES SPINASSI TEIXEIRA | C8: 09/03/2026 | D8: 3 | E8: 3 | F8: CAMPUS CURITIBA | G8: 3541 - MEDICINA - ADM - CTBA (GRADUAÇÃO PRESENCIAL) | H8: SIM | I8: AGUARDANDO APROVAÇÃO | J8: AGUARDANDO APROVAÇÃO | K8: AGUARDANDO APROVAÇÃO | L8: FERIADO | M8: FERIADO | N8: =IF(AND(H8="SIM",E8>0),"Pendência de Agenda",IF(AND(H8="NÃO",E8=0),"Sem Pendência",IF(AND(H8="Sim",E8=0),"Sem Pendência",""))) -> Pendência de Agenda | O8: =IF(AND(D8>0,J8="Finalizado"),"Pendência de TACH",IF(AND(D8>0,J8="Não Criado"),"Pendência de TACH",IF(AND(D8>0,J8="Rascunho"),"Pendência de TACH",IF(AND(D8>0,J8="NECESSÁRIO AJUSTAR"),"Pendência de TACH",IF(AND(D8>0,J8="Aguardando Aprovação"),"Sem Pendência de TACH",IF(AND(D8>0,J8="Aprovado"),"Sem Pendência de TACH",IF(AND(D8>0,K8="Finalizado"),"Pendência de TACH",IF(AND(D8>0,K8="Não Criado"),"Pendência de TACH",IF(AND(D8>0,K8="Rascunho"),"Pendência de TACH",IF(AND(D8>0,K8="NECESSÁRIO AJUSTAR"),"Pendência de TACH",IF(AND(D8>0,K8="Aguardando Aprovação"),"Sem Pendência de TACH",IF(AND(D8>0,K8="Aprovado"),"Sem Pendência de TACH",IF(AND(D8>0,K8="Finalizado"),"Pendência de TACH",IF(AND(D8>0,K8="Não Criado"),"Pendência de TACH",IF(AND(D8>0,K8="Rascunho"),"Pendência de TACH"))))))))))))))) -> Sem Pendência de TACH
A9: 90010315 | B9: FERNANDA CATAFESTA UTZUMI | C9: 07/08/2023 | D9: 20 | E9: 20 | F9: CAMPUS LONDRINA | G9: 105237 - MEDICINA - ADM - LDN (GRADUAÇÃO PRESENCIAL) | H9: SIM | I9: NÃO CRIADO | J9: NÃO CRIADO | K9: NÃO CRIADO | L9: FERIADO | M9: FERIADO | N9: =IF(AND(H9="SIM",E9>0),"Pendência de Agenda",IF(AND(H9="NÃO",E9=0),"Sem Pendência",IF(AND(H9="Sim",E9=0),"Sem Pendência",""))) -> Pendência de Agenda | O9: =IF(AND(D9>0,J9="Finalizado"),"Pendência de TACH",IF(AND(D9>0,J9="Não Criado"),"Pendência de TACH",IF(AND(D9>0,J9="Rascunho"),"Pendência de TACH",IF(AND(D9>0,J9="NECESSÁRIO AJUSTAR"),"Pendência de TACH",IF(AND(D9>0,J9="Aguardando Aprovação"),"Sem Pendência de TACH",IF(AND(D9>0,J9="Aprovado"),"Sem Pendência de TACH",IF(AND(D9>0,K9="Finalizado"),"Pendência de TACH",IF(AND(D9>0,K9="Não Criado"),"Pendência de TACH",IF(AND(D9>0,K9="Rascunho"),"Pendência de TACH",IF(AND(D9>0,K9="NECESSÁRIO AJUSTAR"),"Pendência de TACH",IF(AND(D9>0,K9="Aguardando Aprovação"),"Sem Pendência de TACH",IF(AND(D9>0,K9="Aprovado"),"Sem Pendência de TACH",IF(AND(D9>0,K9="Finalizado"),"Pendência de TACH",IF(AND(D9>0,K9="Não Criado"),"Pendência de TACH",IF(AND(D9>0,K9="Rascunho"),"Pendência de TACH"))))))))))))))) -> Pendência de TACH
A10: 90003306 | B10: HORACIO ALVARENGA MOREIRA | C10: 02/10/2017 | D10: 8 | E10: 8 | F10: CAMPUS LONDRINA | G10: 105237 - MEDICINA - ADM - LDN (GRADUAÇÃO PRESENCIAL) | H10: SIM | I10: NÃO CRIADO | J10: NÃO CRIADO | K10: NÃO CRIADO | L10: FERIADO | M10: FERIADO | N10: =IF(AND(H10="SIM",E10>0),"Pendência de Agenda",IF(AND(H10="NÃO",E10=0),"Sem Pendência",IF(AND(H10="Sim",E10=0),"Sem Pendência",""))) -> Pendência de Agenda | O10: =IF(AND(D10>0,J10="Finalizado"),"Pendência de TACH",IF(AND(D10>0,J10="Não Criado"),"Pendência de TACH",IF(AND(D10>0,J10="Rascunho"),"Pendência de TACH",IF(AND(D10>0,J10="NECESSÁRIO AJUSTAR"),"Pendência de TACH",IF(AND(D10>0,J10="Aguardando Aprovação"),"Sem Pendência de TACH",IF(AND(D10>0,J10="Aprovado"),"Sem Pendência de TACH",IF(AND(D10>0,K10="Finalizado"),"Pendência de TACH",IF(AND(D10>0,K10="Não Criado"),"Pendência de TACH",IF(AND(D10>0,K10="Rascunho"),"Pendência de TACH",IF(AND(D10>0,K10="NECESSÁRIO AJUSTAR"),"Pendência de TACH",IF(AND(D10>0,K10="Aguardando Aprovação"),"Sem Pendência de TACH",IF(AND(D10>0,K10="Aprovado"),"Sem Pendência de TACH",IF(AND(D10>0,K10="Finalizado"),"Pendência de TACH",IF(AND(D10>0,K10="Não Criado"),"Pendência de TACH",IF(AND(D10>0,K10="Rascunho"),"Pendência de TACH"))))))))))))))) -> Pendência de TACH
A11: 90003308 | B11: ISABELA MAYUMI NAKANISHI TAKAKI | C11: 02/10/2017 | D11: 34 | E11: 22 | F11: CAMPUS LONDRINA | G11: 105237 - MEDICINA - ADM - LDN (GRADUAÇÃO PRESENCIAL) | H11: SIM | I11: FINALIZADO | J11: FINALIZADO | K11: APROVADO | L11: FERIADO | M11: FERIADO | N11: =IF(AND(H11="SIM",E11>0),"Pendência de Agenda",IF(AND(H11="NÃO",E11=0),"Sem Pendência",IF(AND(H11="Sim",E11=0),"Sem Pendência",""))) -> Pendência de Agenda | O11: =IF(AND(D11>0,J11="Finalizado"),"Pendência de TACH",IF(AND(D11>0,J11="Não Criado"),"Pendência de TACH",IF(AND(D11>0,J11="Rascunho"),"Pendência de TACH",IF(AND(D11>0,J11="NECESSÁRIO AJUSTAR"),"Pendência de TACH",IF(AND(D11>0,J11="Aguardando Aprovação"),"Sem Pendência de TACH",IF(AND(D11>0,J11="Aprovado"),"Sem Pendência de TACH",IF(AND(D11>0,K11="Finalizado"),"Pendência de TACH",IF(AND(D11>0,K11="Não Criado"),"Pendência de TACH",IF(AND(D11>0,K11="Rascunho"),"Pendência de TACH",IF(AND(D11>0,K11="NECESSÁRIO AJUSTAR"),"Pendência de TACH",IF(AND(D11>0,K11="Aguardando Aprovação"),"Sem Pendência de TACH",IF(AND(D11>0,K11="Aprovado"),"Sem Pendência de TACH",IF(AND(D11>0,K11="Finalizado"),"Pendência de TACH",IF(AND(D11>0,K11="Não Criado"),"Pendência de TACH",IF(AND(D11>0,K11="Rascunho"),"Pendência de TACH"))))))))))))))) -> Pendência de TACH
A12: 90003039 | B12: JAMILE DA COSTA RIECHI | C12: 24/07/2017 | D12: 20 | E12: 2 | F12: CAMPUS LONDRINA | G12: 105237 - MEDICINA - ADM - LDN (GRADUAÇÃO PRESENCIAL) | H12: SIM | I12: APROVADO | J12: APROVADO | K12: APROVADO | L12: FERIADO | M12: FERIADO | N12: =IF(AND(H12="SIM",E12>0),"Pendência de Agenda",IF(AND(H12="NÃO",E12=0),"Sem Pendência",IF(AND(H12="Sim",E12=0),"Sem Pendência",""))) -> Pendência de Agenda | O12: =IF(AND(D12>0,J12="Finalizado"),"Pendência de TACH",IF(AND(D12>0,J12="Não Criado"),"Pendência de TACH",IF(AND(D12>0,J12="Rascunho"),"Pendência de TACH",IF(AND(D12>0,J12="NECESSÁRIO AJUSTAR"),"Pendência de TACH",IF(AND(D12>0,J12="Aguardando Aprovação"),"Sem Pendência de TACH",IF(AND(D12>0,J12="Aprovado"),"Sem Pendência de TACH",IF(AND(D12>0,K12="Finalizado"),"Pendência de TACH",IF(AND(D12>0,K12="Não Criado"),"Pendência de TACH",IF(AND(D12>0,K12="Rascunho"),"Pendência de TACH",IF(AND(D12>0,K12="NECESSÁRIO AJUSTAR"),"Pendência de TACH",IF(AND(D12>0,K12="Aguardando Aprovação"),"Sem Pendência de TACH",IF(AND(D12>0,K12="Aprovado"),"Sem Pendência de TACH",IF(AND(D12>0,K12="Finalizado"),"Pendência de TACH",IF(AND(D12>0,K12="Não Criado"),"Pendência de TACH",IF(AND(D12>0,K12="Rascunho"),"Pendência de TACH"))))))))))))))) -> Sem Pendência de TACH
A13: 90013958 | B13: JEFERSON DA COSTA VAZ | C13: 09/03/2026 | D13: 2 | E13: 2 | F13: CAMPUS CURITIBA | G13: 4267 - FILOSOFIA - ADM - CTBA (GRADUAÇÃO PRESENCIAL) | H13: SIM | I13: NÃO CRIADO | J13: NÃO CRIADO | K13: NÃO CRIADO | L13: FERIADO | M13: FERIADO | N13: =IF(AND(H13="SIM",E13>0),"Pendência de Agenda",IF(AND(H13="NÃO",E13=0),"Sem Pendência",IF(AND(H13="Sim",E13=0),"Sem Pendência",""))) -> Pendência de Agenda | O13: =IF(AND(D13>0,J13="Finalizado"),"Pendência de TACH",IF(AND(D13>0,J13="Não Criado"),"Pendência de TACH",IF(AND(D13>0,J13="Rascunho"),"Pendência de TACH",IF(AND(D13>0,J13="NECESSÁRIO AJUSTAR"),"Pendência de TACH",IF(AND(D13>0,J13="Aguardando Aprovação"),"Sem Pendência de TACH",IF(AND(D13>0,J13="Aprovado"),"Sem Pendência de TACH",IF(AND(D13>0,K13="Finalizado"),"Pendência de TACH",IF(AND(D13>0,K13="Não Criado"),"Pendência de TACH",IF(AND(D13>0,K13="Rascunho"),"Pendência de TACH",IF(AND(D13>0,K13="NECESSÁRIO AJUSTAR"),"Pendência de TACH",IF(AND(D13>0,K13="Aguardando Aprovação"),"Sem Pendência de TACH",IF(AND(D13>0,K13="Aprovado"),"Sem Pendência de TACH",IF(AND(D13>0,K13="Finalizado"),"Pendência de TACH",IF(AND(D13>0,K13="Não Criado"),"Pendência de TACH",IF(AND(D13>0,K13="Rascunho"),"Pendência de TACH"))))))))))))))) -> Pendência de TACH
... A22: 31303 | B22: RICARDO BERNARDO DA SILVA | C22: 10/02/2014 | D22: 28 | E22: 28 | F22: CAMPUS LONDRINA | G22: 105237 - MEDICINA - ADM - LDN (GRADUAÇÃO PRESENCIAL) | H22: SIM | I22: NÃO CRIADO | J22: NÃO CRIADO | K22: NÃO CRIADO | L22: FERIADO | M22: FERIADO | N22: =IF(AND(H22="SIM",E22>0),"Pendência de Agenda",IF(AND(H22="NÃO",E22=0),"Sem Pendência",IF(AND(H22="Sim",E22=0),"Sem Pendência",""))) -> Pendência de Agenda | O22: =IF(AND(D22>0,J22="Finalizado"),"Pendência de TACH",IF(AND(D22>0,J22="Não Criado"),"Pendência de TACH",IF(AND(D22>0,J22="Rascunho"),"Pendência de TACH",IF(AND(D22>0,J22="NECESSÁRIO AJUSTAR"),"Pendência de TACH",IF(AND(D22>0,J22="Aguardando Aprovação"),"Sem Pendência de TACH",IF(AND(D22>0,J22="Aprovado"),"Sem Pendência de TACH",IF(AND(D22>0,K22="Finalizado"),"Pendência de TACH",IF(AND(D22>0,K22="Não Criado"),"Pendência de TACH",IF(AND(D22>0,K22="Rascunho"),"Pendência de TACH",IF(AND(D22>0,K22="NECESSÁRIO AJUSTAR"),"Pendência de TACH",IF(AND(D22>0,K22="Aguardando Aprovação"),"Sem Pendência de TACH",IF(AND(D22>0,K22="Aprovado"),"Sem Pendência de TACH",IF(AND(D22>0,K22="Finalizado"),"Pendência de TACH",IF(AND(D22>0,K22="Não Criado"),"Pendência de TACH",IF(AND(D22>0,K22="Rascunho"),"Pendência de TACH"))))))))))))))) -> Pendência de TACH
A23: 90013903 | B23: JACKSON LUIS SCHIRIGATTI | C23: 02/03/2026 | D23: 6 | E23: 0 | F23: CAMPUS CURITIBA | G23: 1031412 - Cibersegurança - Adm - CTBA (Graduação Presencial) | H23: SIM | I23: NÃO CRIADO | J23: NÃO CRIADO | K23: NÃO CRIADO | L23: FERIADO | M23: FERIADO | N23: =IF(AND(H23="SIM",E23>0),"Pendência de Agenda",IF(AND(H23="NÃO",E23=0),"Sem Pendência",IF(AND(H23="Sim",E23=0),"Sem Pendência",""))) -> Sem Pendência | O23: =IF(AND(D23>0,J23="Finalizado"),"Pendência de TACH",IF(AND(D23>0,J23="Não Criado"),"Pendência de TACH",IF(AND(D23>0,J23="Rascunho"),"Pendência de TACH",IF(AND(D23>0,J23="NECESSÁRIO AJUSTAR"),"Pendência de TACH",IF(AND(D23>0,J23="Aguardando Aprovação"),"Sem Pendência de TACH",IF(AND(D23>0,J23="Aprovado"),"Sem Pendência de TACH",IF(AND(D23>0,K23="Finalizado"),"Pendência de TACH",IF(AND(D23>0,K23="Não Criado"),"Pendência de TACH",IF(AND(D23>0,K23="Rascunho"),"Pendência de TACH",IF(AND(D23>0,K23="NECESSÁRIO AJUSTAR"),"Pendência de TACH",IF(AND(D23>0,K23="Aguardando Aprovação"),"Sem Pendência de TACH",IF(AND(D23>0,K23="Aprovado"),"Sem Pendência de TACH",IF(AND(D23>0,K23="Finalizado"),"Pendência de TACH",IF(AND(D23>0,K23="Não Criado"),"Pendência de TACH",IF(AND(D23>0,K23="Rascunho"),"Pendência de TACH"))))))))))))))) -> Pendência de TACH
A24: 4717 | B24: LUIZ ALBERTO BLANCHET | C24: 02/05/1995 | D24: 28 | E24: 0 | F24: CAMPUS CURITIBA | G24: 4093 - Direito - Adm - CTBA (Graduação Presencial) | H24: NÃO | I24: FINALIZADO | J24: FINALIZADO | K24: FINALIZADO | L24: FERIADO | M24: FERIADO | N24: =IF(AND(H24="SIM",E24>0),"Pendência de Agenda",IF(AND(H24="NÃO",E24=0),"Sem Pendência",IF(AND(H24="Sim",E24=0),"Sem Pendência",""))) -> Sem Pendência | O24: =IF(AND(D24>0,J24="Finalizado"),"Pendência de TACH",IF(AND(D24>0,J24="Não Criado"),"Pendência de TACH",IF(AND(D24>0,J24="Rascunho"),"Pendência de TACH",IF(AND(D24>0,J24="NECESSÁRIO AJUSTAR"),"Pendência de TACH",IF(AND(D24>0,J24="Aguardando Aprovação"),"Sem Pendência de TACH",IF(AND(D24>0,J24="Aprovado"),"Sem Pendência de TACH",IF(AND(D24>0,K24="Finalizado"),"Pendência de TACH",IF(AND(D24>0,K24="Não Criado"),"Pendência de TACH",IF(AND(D24>0,K24="Rascunho"),"Pendência de TACH",IF(AND(D24>0,K24="NECESSÁRIO AJUSTAR"),"Pendência de TACH",IF(AND(D24>0,K24="Aguardando Aprovação"),"Sem Pendência de TACH",IF(AND(D24>0,K24="Aprovado"),"Sem Pendência de TACH",IF(AND(D24>0,K24="Finalizado"),"Pendência de TACH",IF(AND(D24>0,K24="Não Criado"),"Pendência de TACH",IF(AND(D24>0,K24="Rascunho"),"Pendência de TACH"))))))))))))))) -> Pendência de TACH

Sheet 08.06
A1: Matricula | B1: Nome docente | C1: CH total de contrato | D1: Horas a alocar | E1: Campus | F1: Curso | G1: Gera agenda | H1: Status 08/06 | I1: Status 09/06 | J1: Status 10/06 | K1: Status 11/06 | L1: Status 12/06 | M1: Resultado Agenda | N1: Resultado TACH
A2: 8306 | B2: ADALBERTO CARAMORI PETRY | C2: 2 | D2: =_xlfn.XLOOKUP(Table14[[#This Row],[Matricula]],[1]Sheet1!$A:$A,[1]Sheet1!$C:$C,1,0) -> 2 | E2: CAMPUS CURITIBA | F2: 4093 - DIREITO - ADM - CTBA (GRADUAÇÃO PRESENCIAL) | G2: SIM | H2: NÃO CRIADO | I2: NÃO CRIADO | J2: NÃO CRIADO | K2: NÃO CRIADO | L2: NÃO CRIADO | M2: =IF(AND(G2="SIM",D2>0),"Pendência de Agenda",IF(AND(#REF!="NÃO",D2=0),"Sem Pendência",IF(AND(#REF!="Sim",D2=0),"Sem Pendência",""))) -> Pendência de Agenda | N2: {=IF(AND(C2>0,I2="Finalizado"),"Pendência de TACH",IF(AND(C2>0,I2="Não Criado"),"Pendência de TACH",IF(AND(C2>0,I2="Rascunho"),"Pendência de TACH",IF(AND(C2>0,I2="NECESSÁRIO AJUSTAR"),"Pendência de TACH",IF(AND(C2>0,I2="Aguardando Aprovação"),"Sem Pendência de TACH",IF(AND(C2>0,I2="Aprovado"),"Sem Pendência de TACH",IF(AND(C2>0,J2="Finalizado"),"Pendência de TACH",IF(AND(C2>0,J2="Não Criado"),"Pendência de TACH",IF(AND(C2>0,J2="Rascunho"),"Pendência de TACH",IF(AND(C2>0,J2="NECESSÁRIO AJUSTAR"),"Pendência de TACH",IF(AND(C2>0,J2="Aguardando Aprovação"),"Sem Pendência de TACH",IF(AND(C2>0,J2="Aprovado"),"Sem Pendência de TACH",IF(AND(C2>0,K2="Finalizado"),"Pendência de TACH",IF(AND(C2>0,K2="Não Criado"),"Pendência de TACH",IF(AND(C2>0,K2="Rascunho"),"Pendência de TACH",IF(AND(C2>0,K2="NECESSÁRIO AJUSTAR"),"Pendência de TACH",IF(AND(C2>0,K2="Aguardando Aprovação"),"Sem Pendência de TACH",IF(AND(C2>0,K2="Aprovado"),"Sem Pendência de TACH",IF(AND(C2>0,KL="Finalizado"),"Pendência de TACH",IF(AND(C2>0,KL="Não Criado"),"Pendência de TACH",IF(AND(C2>0,KL="Rascunho"),"Pendência de TACH",IF(AND(C2>0,L2="NECESSÁRIO AJUSTAR"),"Pendência de TACH",IF(AND(C2>0,L2="Aguardando Aprovação"),"Sem Pendência de TACH",IF(AND(C2>0,L2="Aprovado"),"Sem Pendência de TACH"))))))))))))))))))))))))} -> Pendência de TACH
A3: 90013836 | B3: ANA LUIZA CHALUSNHAK | C3: 2 | D3: =_xlfn.XLOOKUP(Table14[[#This Row],[Matricula]],[1]Sheet1!$A:$A,[1]Sheet1!$C:$C,1,0) -> 2 | E3: CAMPUS CURITIBA | F3: 4093 - DIREITO - ADM - CTBA (GRADUAÇÃO PRESENCIAL) | G3: SIM | H3: FINALIZADO | I3: FINALIZADO | J3: FINALIZADO | K3: FINALIZADO | L3: FINALIZADO | M3: =IF(AND(G3="SIM",D3>0),"Pendência de Agenda",IF(AND(G3="NÃO",D3=0),"Sem Pendência",IF(AND(G3="Sim",D3=0),"Sem Pendência",""))) -> Pendência de Agenda | N3: {=IF(AND(C3>0,I3="Finalizado"),"Pendência de TACH",IF(AND(C3>0,I3="Não Criado"),"Pendência de TACH",IF(AND(C3>0,I3="Rascunho"),"Pendência de TACH",IF(AND(C3>0,I3="NECESSÁRIO AJUSTAR"),"Pendência de TACH",IF(AND(C3>0,I3="Aguardando Aprovação"),"Sem Pendência de TACH",IF(AND(C3>0,I3="Aprovado"),"Sem Pendência de TACH",IF(AND(C3>0,J3="Finalizado"),"Pendência de TACH",IF(AND(C3>0,J3="Não Criado"),"Pendência de TACH",IF(AND(C3>0,J3="Rascunho"),"Pendência de TACH",IF(AND(C3>0,J3="NECESSÁRIO AJUSTAR"),"Pendência de TACH",IF(AND(C3>0,J3="Aguardando Aprovação"),"Sem Pendência de TACH",IF(AND(C3>0,J3="Aprovado"),"Sem Pendência de TACH",IF(AND(C3>0,K3="Finalizado"),"Pendência de TACH",IF(AND(C3>0,K3="Não Criado"),"Pendência de TACH",IF(AND(C3>0,K3="Rascunho"),"Pendência de TACH",IF(AND(C3>0,K3="NECESSÁRIO AJUSTAR"),"Pendência de TACH",IF(AND(C3>0,K3="Aguardando Aprovação"),"Sem Pendência de TACH",IF(AND(C3>0,K3="Aprovado"),"Sem Pendência de TACH",IF(AND(C3>0,KL="Finalizado"),"Pendência de TACH",IF(AND(C3>0,KL="Não Criado"),"Pendência de TACH",IF(AND(C3>0,KL="Rascunho"),"Pendência de TACH",IF(AND(C3>0,L3="NECESSÁRIO AJUSTAR"),"Pendência de TACH",IF(AND(C3>0,L3="Aguardando Aprovação"),"Sem Pendência de TACH",IF(AND(C3>0,L3="Aprovado"),"Sem Pendência de TACH"))))))))))))))))))))))))} -> Pendência de TACH
A4: 90009703 | B4: ANDERSON NITSCHE | C4: 18 | D4: =_xlfn.XLOOKUP(Table14[[#This Row],[Matricula]],[1]Sheet1!$A:$A,[1]Sheet1!$C:$C,1,0) -> 18 | E4: CAMPUS CURITIBA | F4: 3541 - MEDICINA - ADM - CTBA (GRADUAÇÃO PRESENCIAL) | G4: SIM | H4: RASCUNHO | I4: RASCUNHO | J4: RASCUNHO | K4: RASCUNHO | L4: RASCUNHO | M4: =IF(AND(G4="SIM",D4>0),"Pendência de Agenda",IF(AND(G4="NÃO",D4=0),"Sem Pendência",IF(AND(G4="Sim",D4=0),"Sem Pendência",""))) -> Pendência de Agenda | N4: {=IF(AND(C4>0,I4="Finalizado"),"Pendência de TACH",IF(AND(C4>0,I4="Não Criado"),"Pendência de TACH",IF(AND(C4>0,I4="Rascunho"),"Pendência de TACH",IF(AND(C4>0,I4="NECESSÁRIO AJUSTAR"),"Pendência de TACH",IF(AND(C4>0,I4="Aguardando Aprovação"),"Sem Pendência de TACH",IF(AND(C4>0,I4="Aprovado"),"Sem Pendência de TACH",IF(AND(C4>0,J4="Finalizado"),"Pendência de TACH",IF(AND(C4>0,J4="Não Criado"),"Pendência de TACH",IF(AND(C4>0,J4="Rascunho"),"Pendência de TACH",IF(AND(C4>0,J4="NECESSÁRIO AJUSTAR"),"Pendência de TACH",IF(AND(C4>0,J4="Aguardando Aprovação"),"Sem Pendência de TACH",IF(AND(C4>0,J4="Aprovado"),"Sem Pendência de TACH",IF(AND(C4>0,K4="Finalizado"),"Pendência de TACH",IF(AND(C4>0,K4="Não Criado"),"Pendência de TACH",IF(AND(C4>0,K4="Rascunho"),"Pendência de TACH",IF(AND(C4>0,K4="NECESSÁRIO AJUSTAR"),"Pendência de TACH",IF(AND(C4>0,K4="Aguardando Aprovação"),"Sem Pendência de TACH",IF(AND(C4>0,K4="Aprovado"),"Sem Pendência de TACH",IF(AND(C4>0,KL="Finalizado"),"Pendência de TACH",IF(AND(C4>0,KL="Não Criado"),"Pendência de TACH",IF(AND(C4>0,KL="Rascunho"),"Pendência de TACH",IF(AND(C4>0,L4="NECESSÁRIO AJUSTAR"),"Pendência de TACH",IF(AND(C4>0,L4="Aguardando Aprovação"),"Sem Pendência de TACH",IF(AND(C4>0,L4="Aprovado"),"Sem Pendência de TACH"))))))))))))))))))))))))} -> Pendência de TACH
A5: 90005226 | B5: CESAR RIBEIRO ZUCCOLI | C5: 14 | D5: =_xlfn.XLOOKUP(Table14[[#This Row],[Matricula]],[1]Sheet1!$A:$A,[1]Sheet1!$C:$C,1,0) -> 14 | E5: CAMPUS LONDRINA | F5: 105237 - MEDICINA - ADM - LDN (GRADUAÇÃO PRESENCIAL) | G5: SIM | H5: APROVADO | I5: APROVADO | J5: APROVADO | K5: APROVADO | L5: APROVADO | M5: =IF(AND(G5="SIM",D5>0),"Pendência de Agenda",IF(AND(G5="NÃO",D5=0),"Sem Pendência",IF(AND(G5="Sim",D5=0),"Sem Pendência",""))) -> Pendência de Agenda | N5: {=IF(AND(C5>0,I5="Finalizado"),"Pendência de TACH",IF(AND(C5>0,I5="Não Criado"),"Pendência de TACH",IF(AND(C5>0,I5="Rascunho"),"Pendência de TACH",IF(AND(C5>0,I5="NECESSÁRIO AJUSTAR"),"Pendência de TACH",IF(AND(C5>0,I5="Aguardando Aprovação"),"Sem Pendência de TACH",IF(AND(C5>0,I5="Aprovado"),"Sem Pendência de TACH",IF(AND(C5>0,J5="Finalizado"),"Pendência de TACH",IF(AND(C5>0,J5="Não Criado"),"Pendência de TACH",IF(AND(C5>0,J5="Rascunho"),"Pendência de TACH",IF(AND(C5>0,J5="NECESSÁRIO AJUSTAR"),"Pendência de TACH",IF(AND(C5>0,J5="Aguardando Aprovação"),"Sem Pendência de TACH",IF(AND(C5>0,J5="Aprovado"),"Sem Pendência de TACH",IF(AND(C5>0,K5="Finalizado"),"Pendência de TACH",IF(AND(C5>0,K5="Não Criado"),"Pendência de TACH",IF(AND(C5>0,K5="Rascunho"),"Pendência de TACH",IF(AND(C5>0,K5="NECESSÁRIO AJUSTAR"),"Pendência de TACH",IF(AND(C5>0,K5="Aguardando Aprovação"),"Sem Pendência de TACH",IF(AND(C5>0,K5="Aprovado"),"Sem Pendência de TACH",IF(AND(C5>0,KL="Finalizado"),"Pendência de TACH",IF(AND(C5>0,KL="Não Criado"),"Pendência de TACH",IF(AND(C5>0,KL="Rascunho"),"Pendência de TACH",IF(AND(C5>0,L5="NECESSÁRIO AJUSTAR"),"Pendência de TACH",IF(AND(C5>0,L5="Aguardando Aprovação"),"Sem Pendência de TACH",IF(AND(C5>0,L5="Aprovado"),"Sem Pendência de TACH"))))))))))))))))))))))))} -> Sem Pendência de TACH
A6: 90013955 | B6: EMILE FERNANDES SPINASSI TEIXEIRA | C6: 3 | D6: =_xlfn.XLOOKUP(Table14[[#This Row],[Matricula]],[1]Sheet1!$A:$A,[1]Sheet1!$C:$C,1,0) -> 3 | E6: CAMPUS CURITIBA | F6: 3541 - MEDICINA - ADM - CTBA (GRADUAÇÃO PRESENCIAL) | G6: SIM | H6: AGUARDANDO APROVAÇÃO | I6: AGUARDANDO APROVAÇÃO | J6: AGUARDANDO APROVAÇÃO | K6: AGUARDANDO APROVAÇÃO | L6: AGUARDANDO APROVAÇÃO | M6: =IF(AND(G6="SIM",D6>0),"Pendência de Agenda",IF(AND(G6="NÃO",D6=0),"Sem Pendência",IF(AND(G6="Sim",D6=0),"Sem Pendência",""))) -> Pendência de Agenda | N6: {=IF(AND(C6>0,I6="Finalizado"),"Pendência de TACH",IF(AND(C6>0,I6="Não Criado"),"Pendência de TACH",IF(AND(C6>0,I6="Rascunho"),"Pendência de TACH",IF(AND(C6>0,I6="NECESSÁRIO AJUSTAR"),"Pendência de TACH",IF(AND(C6>0,I6="Aguardando Aprovação"),"Sem Pendência de TACH",IF(AND(C6>0,I6="Aprovado"),"Sem Pendência de TACH",IF(AND(C6>0,J6="Finalizado"),"Pendência de TACH",IF(AND(C6>0,J6="Não Criado"),"Pendência de TACH",IF(AND(C6>0,J6="Rascunho"),"Pendência de TACH",IF(AND(C6>0,J6="NECESSÁRIO AJUSTAR"),"Pendência de TACH",IF(AND(C6>0,J6="Aguardando Aprovação"),"Sem Pendência de TACH",IF(AND(C6>0,J6="Aprovado"),"Sem Pendência de TACH",IF(AND(C6>0,K6="Finalizado"),"Pendência de TACH",IF(AND(C6>0,K6="Não Criado"),"Pendência de TACH",IF(AND(C6>0,K6="Rascunho"),"Pendência de TACH",IF(AND(C6>0,K6="NECESSÁRIO AJUSTAR"),"Pendência de TACH",IF(AND(C6>0,K6="Aguardando Aprovação"),"Sem Pendência de TACH",IF(AND(C6>0,K6="Aprovado"),"Sem Pendência de TACH",IF(AND(C6>0,KL="Finalizado"),"Pendência de TACH",IF(AND(C6>0,KL="Não Criado"),"Pendência de TACH",IF(AND(C6>0,KL="Rascunho"),"Pendência de TACH",IF(AND(C6>0,L6="NECESSÁRIO AJUSTAR"),"Pendência de TACH",IF(AND(C6>0,L6="Aguardando Aprovação"),"Sem Pendência de TACH",IF(AND(C6>0,L6="Aprovado"),"Sem Pendência de TACH"))))))))))))))))))))))))} -> Sem Pendência de TACH
A7: 90010315 | B7: FERNANDA CATAFESTA UTZUMI | C7: 20 | D7: =_xlfn.XLOOKUP(Table14[[#This Row],[Matricula]],[1]Sheet1!$A:$A,[1]Sheet1!$C:$C,1,0) -> 20 | E7: CAMPUS LONDRINA | F7: 105237 - MEDICINA - ADM - LDN (GRADUAÇÃO PRESENCIAL) | G7: SIM | H7: NÃO CRIADO | I7: AGUARDANDO APROVAÇÃO | J7: AGUARDANDO APROVAÇÃO | K7: APROVADO | L7: APROVADO | M7: =IF(AND(G7="SIM",D7>0),"Pendência de Agenda",IF(AND(G7="NÃO",D7=0),"Sem Pendência",IF(AND(G7="Sim",D7=0),"Sem Pendência",""))) -> Pendência de Agenda | N7: {=IF(AND(C7>0,I7="Finalizado"),"Pendência de TACH",IF(AND(C7>0,I7="Não Criado"),"Pendência de TACH",IF(AND(C7>0,I7="Rascunho"),"Pendência de TACH",IF(AND(C7>0,I7="NECESSÁRIO AJUSTAR"),"Pendência de TACH",IF(AND(C7>0,I7="Aguardando Aprovação"),"Sem Pendência de TACH",IF(AND(C7>0,I7="Aprovado"),"Sem Pendência de TACH",IF(AND(C7>0,J7="Finalizado"),"Pendência de TACH",IF(AND(C7>0,J7="Não Criado"),"Pendência de TACH",IF(AND(C7>0,J7="Rascunho"),"Pendência de TACH",IF(AND(C7>0,J7="NECESSÁRIO AJUSTAR"),"Pendência de TACH",IF(AND(C7>0,J7="Aguardando Aprovação"),"Sem Pendência de TACH",IF(AND(C7>0,J7="Aprovado"),"Sem Pendência de TACH",IF(AND(C7>0,K7="Finalizado"),"Pendência de TACH",IF(AND(C7>0,K7="Não Criado"),"Pendência de TACH",IF(AND(C7>0,K7="Rascunho"),"Pendência de TACH",IF(AND(C7>0,K7="NECESSÁRIO AJUSTAR"),"Pendência de TACH",IF(AND(C7>0,K7="Aguardando Aprovação"),"Sem Pendência de TACH",IF(AND(C7>0,K7="Aprovado"),"Sem Pendência de TACH",IF(AND(C7>0,KL="Finalizado"),"Pendência de TACH",IF(AND(C7>0,KL="Não Criado"),"Pendência de TACH",IF(AND(C7>0,KL="Rascunho"),"Pendência de TACH",IF(AND(C7>0,L7="NECESSÁRIO AJUSTAR"),"Pendência de TACH",IF(AND(C7>0,L7="Aguardando Aprovação"),"Sem Pendência de TACH",IF(AND(C7>0,L7="Aprovado"),"Sem Pendência de TACH"))))))))))))))))))))))))} -> Sem Pendência de TACH
A8: 90003306 | B8: HORACIO ALVARENGA MOREIRA | C8: 8 | D8: =_xlfn.XLOOKUP(Table14[[#This Row],[Matricula]],[1]Sheet1!$A:$A,[1]Sheet1!$C:$C,1,0) -> 8 | E8: CAMPUS LONDRINA | F8: 105237 - MEDICINA - ADM - LDN (GRADUAÇÃO PRESENCIAL) | G8: SIM | H8: NÃO CRIADO | I8: NÃO CRIADO | J8: NÃO CRIADO | K8: NÃO CRIADO | L8: NÃO CRIADO | M8: =IF(AND(G8="SIM",D8>0),"Pendência de Agenda",IF(AND(G8="NÃO",D8=0),"Sem Pendência",IF(AND(G8="Sim",D8=0),"Sem Pendência",""))) -> Pendência de Agenda | N8: {=IF(AND(C8>0,I8="Finalizado"),"Pendência de TACH",IF(AND(C8>0,I8="Não Criado"),"Pendência de TACH",IF(AND(C8>0,I8="Rascunho"),"Pendência de TACH",IF(AND(C8>0,I8="NECESSÁRIO AJUSTAR"),"Pendência de TACH",IF(AND(C8>0,I8="Aguardando Aprovação"),"Sem Pendência de TACH",IF(AND(C8>0,I8="Aprovado"),"Sem Pendência de TACH",IF(AND(C8>0,J8="Finalizado"),"Pendência de TACH",IF(AND(C8>0,J8="Não Criado"),"Pendência de TACH",IF(AND(C8>0,J8="Rascunho"),"Pendência de TACH",IF(AND(C8>0,J8="NECESSÁRIO AJUSTAR"),"Pendência de TACH",IF(AND(C8>0,J8="Aguardando Aprovação"),"Sem Pendência de TACH",IF(AND(C8>0,J8="Aprovado"),"Sem Pendência de TACH",IF(AND(C8>0,K8="Finalizado"),"Pendência de TACH",IF(AND(C8>0,K8="Não Criado"),"Pendência de TACH",IF(AND(C8>0,K8="Rascunho"),"Pendência de TACH",IF(AND(C8>0,K8="NECESSÁRIO AJUSTAR"),"Pendência de TACH",IF(AND(C8>0,K8="Aguardando Aprovação"),"Sem Pendência de TACH",IF(AND(C8>0,K8="Aprovado"),"Sem Pendência de TACH",IF(AND(C8>0,KL="Finalizado"),"Pendência de TACH",IF(AND(C8>0,KL="Não Criado"),"Pendência de TACH",IF(AND(C8>0,KL="Rascunho"),"Pendência de TACH",IF(AND(C8>0,L8="NECESSÁRIO AJUSTAR"),"Pendência de TACH",IF(AND(C8>0,L8="Aguardando Aprovação"),"Sem Pendência de TACH",IF(AND(C8>0,L8="Aprovado"),"Sem Pendência de TACH"))))))))))))))))))))))))} -> Pendência de TACH
A9: 23702 | B9: HUMBERTO MACIEL FRANCA MADEIRA | C9: 22 | D9: =_xlfn.XLOOKUP(Table14[[#This Row],[Matricula]],[1]Sheet1!$A:$A,[1]Sheet1!$C:$C,1,0) -> 22 | E9: CAMPUS CURITIBA | F9: 103572 - BIOTECNOLOGIA - ADM - CTBA (GRADUAÇÃO PRESENCIAL) | G9: SIM | H9: FINALIZADO | I9: FINALIZADO | J9: FINALIZADO | K9: FINALIZADO | L9: AGUARDANDO APROVAÇÃO | M9: =IF(AND(G9="SIM",D9>0),"Pendência de Agenda",IF(AND(G9="NÃO",D9=0),"Sem Pendência",IF(AND(G9="Sim",D9=0),"Sem Pendência",""))) -> Pendência de Agenda | N9: {=IF(AND(C9>0,I9="Finalizado"),"Pendência de TACH",IF(AND(C9>0,I9="Não Criado"),"Pendência de TACH",IF(AND(C9>0,I9="Rascunho"),"Pendência de TACH",IF(AND(C9>0,I9="NECESSÁRIO AJUSTAR"),"Pendência de TACH",IF(AND(C9>0,I9="Aguardando Aprovação"),"Sem Pendência de TACH",IF(AND(C9>0,I9="Aprovado"),"Sem Pendência de TACH",IF(AND(C9>0,J9="Finalizado"),"Pendência de TACH",IF(AND(C9>0,J9="Não Criado"),"Pendência de TACH",IF(AND(C9>0,J9="Rascunho"),"Pendência de TACH",IF(AND(C9>0,J9="NECESSÁRIO AJUSTAR"),"Pendência de TACH",IF(AND(C9>0,J9="Aguardando Aprovação"),"Sem Pendência de TACH",IF(AND(C9>0,J9="Aprovado"),"Sem Pendência de TACH",IF(AND(C9>0,K9="Finalizado"),"Pendência de TACH",IF(AND(C9>0,K9="Não Criado"),"Pendência de TACH",IF(AND(C9>0,K9="Rascunho"),"Pendência de TACH",IF(AND(C9>0,K9="NECESSÁRIO AJUSTAR"),"Pendência de TACH",IF(AND(C9>0,K9="Aguardando Aprovação"),"Sem Pendência de TACH",IF(AND(C9>0,K9="Aprovado"),"Sem Pendência de TACH",IF(AND(C9>0,KL="Finalizado"),"Pendência de TACH",IF(AND(C9>0,KL="Não Criado"),"Pendência de TACH",IF(AND(C9>0,KL="Rascunho"),"Pendência de TACH",IF(AND(C9>0,L9="NECESSÁRIO AJUSTAR"),"Pendência de TACH",IF(AND(C9>0,L9="Aguardando Aprovação"),"Sem Pendência de TACH",IF(AND(C9>0,L9="Aprovado"),"Sem Pendência de TACH"))))))))))))))))))))))))} -> Pendência de TACH
A10: 90013958 | B10: JEFERSON DA COSTA VAZ | C10: 2 | D10: =_xlfn.XLOOKUP(Table14[[#This Row],[Matricula]],[1]Sheet1!$A:$A,[1]Sheet1!$C:$C,1,0) -> 2 | E10: CAMPUS CURITIBA | F10: 4267 - FILOSOFIA - ADM - CTBA (GRADUAÇÃO PRESENCIAL) | G10: SIM | H10: NÃO CRIADO | I10: NÃO CRIADO | J10: NÃO CRIADO | K10: NÃO CRIADO | L10: NÃO CRIADO | M10: =IF(AND(G10="SIM",D10>0),"Pendência de Agenda",IF(AND(G10="NÃO",D10=0),"Sem Pendência",IF(AND(G10="Sim",D10=0),"Sem Pendência",""))) -> Pendência de Agenda | N10: {=IF(AND(C10>0,I10="Finalizado"),"Pendência de TACH",IF(AND(C10>0,I10="Não Criado"),"Pendência de TACH",IF(AND(C10>0,I10="Rascunho"),"Pendência de TACH",IF(AND(C10>0,I10="NECESSÁRIO AJUSTAR"),"Pendência de TACH",IF(AND(C10>0,I10="Aguardando Aprovação"),"Sem Pendência de TACH",IF(AND(C10>0,I10="Aprovado"),"Sem Pendência de TACH",IF(AND(C10>0,J10="Finalizado"),"Pendência de TACH",IF(AND(C10>0,J10="Não Criado"),"Pendência de TACH",IF(AND(C10>0,J10="Rascunho"),"Pendência de TACH",IF(AND(C10>0,J10="NECESSÁRIO AJUSTAR"),"Pendência de TACH",IF(AND(C10>0,J10="Aguardando Aprovação"),"Sem Pendência de TACH",IF(AND(C10>0,J10="Aprovado"),"Sem Pendência de TACH",IF(AND(C10>0,K10="Finalizado"),"Pendência de TACH",IF(AND(C10>0,K10="Não Criado"),"Pendência de TACH",IF(AND(C10>0,K10="Rascunho"),"Pendência de TACH",IF(AND(C10>0,K10="NECESSÁRIO AJUSTAR"),"Pendência de TACH",IF(AND(C10>0,K10="Aguardando Aprovação"),"Sem Pendência de TACH",IF(AND(C10>0,K10="Aprovado"),"Sem Pendência de TACH",IF(AND(C10>0,KL="Finalizado"),"Pendência de TACH",IF(AND(C10>0,KL="Não Criado"),"Pendência de TACH",IF(AND(C10>0,KL="Rascunho"),"Pendência de TACH",IF(AND(C10>0,L10="NECESSÁRIO AJUSTAR"),"Pendência de TACH",IF(AND(C10>0,L10="Aguardando Aprovação"),"Sem Pendência de TACH",IF(AND(C10>0,L10="Aprovado"),"Sem Pendência de TACH"))))))))))))))))))))))))} -> Pendência de TACH
A11: 90005652 | B11: JULIANA CONCEICAO NOSCHANG DA COSTA | C11: 36 | D11: =_xlfn.XLOOKUP(Table14[[#This Row],[Matricula]],[1]Sheet1!$A:$A,[1]Sheet1!$C:$C,1,0) -> 3 | E11: CAMPUS CURITIBA | F11: 103371 - MARKETING - ADM - CTBA (GRADUAÇÃO PRESENCIAL) | G11: SIM | H11: APROVADO | I11: APROVADO | J11: APROVADO | K11: APROVADO | L11: APROVADO | M11: =IF(AND(G11="SIM",D11>0),"Pendência de Agenda",IF(AND(G11="NÃO",D11=0),"Sem Pendência",IF(AND(G11="Sim",D11=0),"Sem Pendência",""))) -> Pendência de Agenda | N11: {=IF(AND(C11>0,I11="Finalizado"),"Pendência de TACH",IF(AND(C11>0,I11="Não Criado"),"Pendência de TACH",IF(AND(C11>0,I11="Rascunho"),"Pendência de TACH",IF(AND(C11>0,I11="NECESSÁRIO AJUSTAR"),"Pendência de TACH",IF(AND(C11>0,I11="Aguardando Aprovação"),"Sem Pendência de TACH",IF(AND(C11>0,I11="Aprovado"),"Sem Pendência de TACH",IF(AND(C11>0,J11="Finalizado"),"Pendência de TACH",IF(AND(C11>0,J11="Não Criado"),"Pendência de TACH",IF(AND(C11>0,J11="Rascunho"),"Pendência de TACH",IF(AND(C11>0,J11="NECESSÁRIO AJUSTAR"),"Pendência de TACH",IF(AND(C11>0,J11="Aguardando Aprovação"),"Sem Pendência de TACH",IF(AND(C11>0,J11="Aprovado"),"Sem Pendência de TACH",IF(AND(C11>0,K11="Finalizado"),"Pendência de TACH",IF(AND(C11>0,K11="Não Criado"),"Pendência de TACH",IF(AND(C11>0,K11="Rascunho"),"Pendência de TACH",IF(AND(C11>0,K11="NECESSÁRIO AJUSTAR"),"Pendência de TACH",IF(AND(C11>0,K11="Aguardando Aprovação"),"Sem Pendência de TACH",IF(AND(C11>0,K11="Aprovado"),"Sem Pendência de TACH",IF(AND(C11>0,KL="Finalizado"),"Pendência de TACH",IF(AND(C11>0,KL="Não Criado"),"Pendência de TACH",IF(AND(C11>0,KL="Rascunho"),"Pendência de TACH",IF(AND(C11>0,L11="NECESSÁRIO AJUSTAR"),"Pendência de TACH",IF(AND(C11>0,L11="Aguardando Aprovação"),"Sem Pendência de TACH",IF(AND(C11>0,L11="Aprovado"),"Sem Pendência de TACH"))))))))))))))))))))))))} -> Sem Pendência de TACH
A12: 90001409 | B12: LUIZ CARLOS CANTANHEDE FERNANDES JUNIOR | C12: 20 | D12: =_xlfn.XLOOKUP(Table14[[#This Row],[Matricula]],[1]Sheet1!$A:$A,[1]Sheet1!$C:$C,1,0) -> 20 | E12: CAMPUS LONDRINA | F12: 105237 - MEDICINA - ADM - LDN (GRADUAÇÃO PRESENCIAL) | G12: SIM | H12: NÃO CRIADO | I12: NÃO CRIADO | J12: NÃO CRIADO | K12: NÃO CRIADO | L12: NÃO CRIADO | M12: =IF(AND(G12="SIM",D12>0),"Pendência de Agenda",IF(AND(G12="NÃO",D12=0),"Sem Pendência",IF(AND(G12="Sim",D12=0),"Sem Pendência",""))) -> Pendência de Agenda | N12: {=IF(AND(C12>0,I12="Finalizado"),"Pendência de TACH",IF(AND(C12>0,I12="Não Criado"),"Pendência de TACH",IF(AND(C12>0,I12="Rascunho"),"Pendência de TACH",IF(AND(C12>0,I12="NECESSÁRIO AJUSTAR"),"Pendência de TACH",IF(AND(C12>0,I12="Aguardando Aprovação"),"Sem Pendência de TACH",IF(AND(C12>0,I12="Aprovado"),"Sem Pendência de TACH",IF(AND(C12>0,J12="Finalizado"),"Pendência de TACH",IF(AND(C12>0,J12="Não Criado"),"Pendência de TACH",IF(AND(C12>0,J12="Rascunho"),"Pendência de TACH",IF(AND(C12>0,J12="NECESSÁRIO AJUSTAR"),"Pendência de TACH",IF(AND(C12>0,J12="Aguardando Aprovação"),"Sem Pendência de TACH",IF(AND(C12>0,J12="Aprovado"),"Sem Pendência de TACH",IF(AND(C12>0,K12="Finalizado"),"Pendência de TACH",IF(AND(C12>0,K12="Não Criado"),"Pendência de TACH",IF(AND(C12>0,K12="Rascunho"),"Pendência de TACH",IF(AND(C12>0,K12="NECESSÁRIO AJUSTAR"),"Pendência de TACH",IF(AND(C12>0,K12="Aguardando Aprovação"),"Sem Pendência de TACH",IF(AND(C12>0,K12="Aprovado"),"Sem Pendência de TACH",IF(AND(C12>0,KL="Finalizado"),"Pendência de TACH",IF(AND(C12>0,KL="Não Criado"),"Pendência de TACH",IF(AND(C12>0,KL="Rascunho"),"Pendência de TACH",IF(AND(C12>0,L12="NECESSÁRIO AJUSTAR"),"Pendência de TACH",IF(AND(C12>0,L12="Aguardando Aprovação"),"Sem Pendência de TACH",IF(AND(C12>0,L12="Aprovado"),"Sem Pendência de TACH"))))))))))))))))))))))))} -> Pendência de TACH
A13: 90009989 | B13: MANOEL VALERIO DA SILVEIRA NETO | C13: 2 | D13: =_xlfn.XLOOKUP(Table14[[#This Row],[Matricula]],[1]Sheet1!$A:$A,[1]Sheet1!$C:$C,1,0) -> 2 | E13: CAMPUS CURITIBA | F13: 103974 - ENGENHARIA DE SOFTWARE - ADM - CTBA (GRADUAÇÃO PRESENCIAL) | G13: SIM | H13: APROVADO | I13: APROVADO | J13: APROVADO | K13: APROVADO | L13: APROVADO | M13: =IF(AND(G13="SIM",D13>0),"Pendência de Agenda",IF(AND(G13="NÃO",D13=0),"Sem Pendência",IF(AND(G13="Sim",D13=0),"Sem Pendência",""))) -> Pendência de Agenda | N13: {=IF(AND(C13>0,I13="Finalizado"),"Pendência de TACH",IF(AND(C13>0,I13="Não Criado"),"Pendência de TACH",IF(AND(C13>0,I13="Rascunho"),"Pendência de TACH",IF(AND(C13>0,I13="NECESSÁRIO AJUSTAR"),"Pendência de TACH",IF(AND(C13>0,I13="Aguardando Aprovação"),"Sem Pendência de TACH",IF(AND(C13>0,I13="Aprovado"),"Sem Pendência de TACH",IF(AND(C13>0,J13="Finalizado"),"Pendência de TACH",IF(AND(C13>0,J13="Não Criado"),"Pendência de TACH",IF(AND(C13>0,J13="Rascunho"),"Pendência de TACH",IF(AND(C13>0,J13="NECESSÁRIO AJUSTAR"),"Pendência de TACH",IF(AND(C13>0,J13="Aguardando Aprovação"),"Sem Pendência de TACH",IF(AND(C13>0,J13="Aprovado"),"Sem Pendência de TACH",IF(AND(C13>0,K13="Finalizado"),"Pendência de TACH",IF(AND(C13>0,K13="Não Criado"),"Pendência de TACH",IF(AND(C13>0,K13="Rascunho"),"Pendência de TACH",IF(AND(C13>0,K13="NECESSÁRIO AJUSTAR"),"Pendência de TACH",IF(AND(C13>0,K13="Aguardando Aprovação"),"Sem Pendência de TACH",IF(AND(C13>0,K13="Aprovado"),"Sem Pendência de TACH",IF(AND(C13>0,KL="Finalizado"),"Pendência de TACH",IF(AND(C13>0,KL="Não Criado"),"Pendência de TACH",IF(AND(C13>0,KL="Rascunho"),"Pendência de TACH",IF(AND(C13>0,L13="NECESSÁRIO AJUSTAR"),"Pendência de TACH",IF(AND(C13>0,L13="Aguardando Aprovação"),"Sem Pendência de TACH",IF(AND(C13>0,L13="Aprovado"),"Sem Pendência de TACH"))))))))))))))))))))))))} -> Sem Pendência de TACH
A14: 90012360 | B14: MANUELA TORRADO TRUITI | C14: 16 | D14: =_xlfn.XLOOKUP(Table14[[#This Row],[Matricula]],[1]Sheet1!$A:$A,[1]Sheet1!$C:$C,1,0) -> 16 | E14: CAMPUS TOLEDO | F14: 112339 - MEDICINA - ADM - TLD (GRADUAÇÃO PRESENCIAL) | G14: SIM | H14: NÃO CRIADO | I14: NÃO CRIADO | J14: NÃO CRIADO | K14: NÃO CRIADO | L14: NÃO CRIADO | M14: =IF(AND(G14="SIM",D14>0),"Pendência de Agenda",IF(AND(G14="NÃO",D14=0),"Sem Pendência",IF(AND(G14="Sim",D14=0),"Sem Pendência",""))) -> Pendência de Agenda | N14: {=IF(AND(C14>0,I14="Finalizado"),"Pendência de TACH",IF(AND(C14>0,I14="Não Criado"),"Pendência de TACH",IF(AND(C14>0,I14="Rascunho"),"Pendência de TACH",IF(AND(C14>0,I14="NECESSÁRIO AJUSTAR"),"Pendência de TACH",IF(AND(C14>0,I14="Aguardando Aprovação"),"Sem Pendência de TACH",IF(AND(C14>0,I14="Aprovado"),"Sem Pendência de TACH",IF(AND(C14>0,J14="Finalizado"),"Pendência de TACH",IF(AND(C14>0,J14="Não Criado"),"Pendência de TACH",IF(AND(C14>0,J14="Rascunho"),"Pendência de TACH",IF(AND(C14>0,J14="NECESSÁRIO AJUSTAR"),"Pendência de TACH",IF(AND(C14>0,J14="Aguardando Aprovação"),"Sem Pendência de TACH",IF(AND(C14>0,J14="Aprovado"),"Sem Pendência de TACH",IF(AND(C14>0,K14="Finalizado"),"Pendência de TACH",IF(AND(C14>0,K14="Não Criado"),"Pendência de TACH",IF(AND(C14>0,K14="Rascunho"),"Pendência de TACH",IF(AND(C14>0,K14="NECESSÁRIO AJUSTAR"),"Pendência de TACH",IF(AND(C14>0,K14="Aguardando Aprovação"),"Sem Pendência de TACH",IF(AND(C14>0,K14="Aprovado"),"Sem Pendência de TACH",IF(AND(C14>0,KL="Finalizado"),"Pendência de TACH",IF(AND(C14>0,KL="Não Criado"),"Pendência de TACH",IF(AND(C14>0,KL="Rascunho"),"Pendência de TACH",IF(AND(C14>0,L14="NECESSÁRIO AJUSTAR"),"Pendência de TACH",IF(AND(C14>0,L14="Aguardando Aprovação"),"Sem Pendência de TACH",IF(AND(C14>0,L14="Aprovado"),"Sem Pendência de TACH"))))))))))))))))))))))))} -> Pendência de TACH
... A19: 31303 | B19: RICARDO BERNARDO DA SILVA | C19: 28 | D19: =_xlfn.XLOOKUP(Table14[[#This Row],[Matricula]],[1]Sheet1!$A:$A,[1]Sheet1!$C:$C,1,0) -> 28 | E19: CAMPUS LONDRINA | F19: 105237 - MEDICINA - ADM - LDN (GRADUAÇÃO PRESENCIAL) | G19: SIM | H19: NÃO CRIADO | I19: NÃO CRIADO | J19: NÃO CRIADO | K19: NÃO CRIADO | L19: NÃO CRIADO | M19: =IF(AND(G19="SIM",D19>0),"Pendência de Agenda",IF(AND(G19="NÃO",D19=0),"Sem Pendência",IF(AND(G19="Sim",D19=0),"Sem Pendência",""))) -> Pendência de Agenda | N19: {=IF(AND(C19>0,I19="Finalizado"),"Pendência de TACH",IF(AND(C19>0,I19="Não Criado"),"Pendência de TACH",IF(AND(C19>0,I19="Rascunho"),"Pendência de TACH",IF(AND(C19>0,I19="NECESSÁRIO AJUSTAR"),"Pendência de TACH",IF(AND(C19>0,I19="Aguardando Aprovação"),"Sem Pendência de TACH",IF(AND(C19>0,I19="Aprovado"),"Sem Pendência de TACH",IF(AND(C19>0,J19="Finalizado"),"Pendência de TACH",IF(AND(C19>0,J19="Não Criado"),"Pendência de TACH",IF(AND(C19>0,J19="Rascunho"),"Pendência de TACH",IF(AND(C19>0,J19="NECESSÁRIO AJUSTAR"),"Pendência de TACH",IF(AND(C19>0,J19="Aguardando Aprovação"),"Sem Pendência de TACH",IF(AND(C19>0,J19="Aprovado"),"Sem Pendência de TACH",IF(AND(C19>0,K19="Finalizado"),"Pendência de TACH",IF(AND(C19>0,K19="Não Criado"),"Pendência de TACH",IF(AND(C19>0,K19="Rascunho"),"Pendência de TACH",IF(AND(C19>0,K19="NECESSÁRIO AJUSTAR"),"Pendência de TACH",IF(AND(C19>0,K19="Aguardando Aprovação"),"Sem Pendência de TACH",IF(AND(C19>0,K19="Aprovado"),"Sem Pendência de TACH",IF(AND(C19>0,KL="Finalizado"),"Pendência de TACH",IF(AND(C19>0,KL="Não Criado"),"Pendência de TACH",IF(AND(C19>0,KL="Rascunho"),"Pendência de TACH",IF(AND(C19>0,L19="NECESSÁRIO AJUSTAR"),"Pendência de TACH",IF(AND(C19>0,L19="Aguardando Aprovação"),"Sem Pendência de TACH",IF(AND(C19>0,L19="Aprovado"),"Sem Pendência de TACH"))))))))))))))))))))))))} -> Pendência de TACH
A20: 90014322 | B20: CARINA FERNANDA MATTEDI | C20: 12 | D20: 0 | E20: CAMPUS CURITIBA | F20: 10326554 - Biomedicina - Adm - CTBA (Graduação Presencial) | G20: SIM | H20: NÃO CRIADO | I20: NÃO CRIADO | J20: AGUARDANDO APROVAÇÃO | K20: APROVADO | L20: APROVADO | M20: =IF(AND(G20="SIM",D20>0),"Pendência de Agenda",IF(AND(G20="NÃO",D20=0),"Sem Pendência",IF(AND(G20="Sim",D20=0),"Sem Pendência",""))) -> Sem Pendência | N20: {=IF(AND(C20>0,I20="Finalizado"),"Pendência de TACH",IF(AND(C20>0,I20="Não Criado"),"Pendência de TACH",IF(AND(C20>0,I20="Rascunho"),"Pendência de TACH",IF(AND(C20>0,I20="NECESSÁRIO AJUSTAR"),"Pendência de TACH",IF(AND(C20>0,I20="Aguardando Aprovação"),"Sem Pendência de TACH",IF(AND(C20>0,I20="Aprovado"),"Sem Pendência de TACH",IF(AND(C20>0,J20="Finalizado"),"Pendência de TACH",IF(AND(C20>0,J20="Não Criado"),"Pendência de TACH",IF(AND(C20>0,J20="Rascunho"),"Pendência de TACH",IF(AND(C20>0,J20="NECESSÁRIO AJUSTAR"),"Pendência de TACH",IF(AND(C20>0,J20="Aguardando Aprovação"),"Sem Pendência de TACH",IF(AND(C20>0,J20="Aprovado"),"Sem Pendência de TACH",IF(AND(C20>0,K20="Finalizado"),"Pendência de TACH",IF(AND(C20>0,K20="Não Criado"),"Pendência de TACH",IF(AND(C20>0,K20="Rascunho"),"Pendência de TACH",IF(AND(C20>0,K20="NECESSÁRIO AJUSTAR"),"Pendência de TACH",IF(AND(C20>0,K20="Aguardando Aprovação"),"Sem Pendência de TACH",IF(AND(C20>0,K20="Aprovado"),"Sem Pendência de TACH",IF(AND(C20>0,KL="Finalizado"),"Pendência de TACH",IF(AND(C20>0,KL="Não Criado"),"Pendência de TACH",IF(AND(C20>0,KL="Rascunho"),"Pendência de TACH",IF(AND(C20>0,L20="NECESSÁRIO AJUSTAR"),"Pendência de TACH",IF(AND(C20>0,L20="Aguardando Aprovação"),"Sem Pendência de TACH",IF(AND(C20>0,L20="Aprovado"),"Sem Pendência de TACH"))))))))))))))))))))))))} -> Pendência de TACH
A21: 90002589 | B21: JOSE EDUARDO NUNES LINO | C21: 28 | D21: 0 | E21: CAMPUS CURITIBA | F21: 3776 - Ciência da Computação - Adm - CTBA (Graduação Presencial) | G21: NÃO | H21: FINALIZADO | I21: FINALIZADO | J21: FINALIZADO | K21: FINALIZADO | L21: APROVADO | M21: =IF(AND(G21="SIM",D21>0),"Pendência de Agenda",IF(AND(G21="NÃO",D21=0),"Sem Pendência",IF(AND(G21="Sim",D21=0),"Sem Pendência",""))) -> Sem Pendência | N21: {=IF(AND(C21>0,I21="Finalizado"),"Pendência de TACH",IF(AND(C21>0,I21="Não Criado"),"Pendência de TACH",IF(AND(C21>0,I21="Rascunho"),"Pendência de TACH",IF(AND(C21>0,I21="NECESSÁRIO AJUSTAR"),"Pendência de TACH",IF(AND(C21>0,I21="Aguardando Aprovação"),"Sem Pendência de TACH",IF(AND(C21>0,I21="Aprovado"),"Sem Pendência de TACH",IF(AND(C21>0,J21="Finalizado"),"Pendência de TACH",IF(AND(C21>0,J21="Não Criado"),"Pendência de TACH",IF(AND(C21>0,J21="Rascunho"),"Pendência de TACH",IF(AND(C21>0,J21="NECESSÁRIO AJUSTAR"),"Pendência de TACH",IF(AND(C21>0,J21="Aguardando Aprovação"),"Sem Pendência de TACH",IF(AND(C21>0,J21="Aprovado"),"Sem Pendência de TACH",IF(AND(C21>0,K21="Finalizado"),"Pendência de TACH",IF(AND(C21>0,K21="Não Criado"),"Pendência de TACH",IF(AND(C21>0,K21="Rascunho"),"Pendência de TACH",IF(AND(C21>0,K21="NECESSÁRIO AJUSTAR"),"Pendência de TACH",IF(AND(C21>0,K21="Aguardando Aprovação"),"Sem Pendência de TACH",IF(AND(C21>0,K21="Aprovado"),"Sem Pendência de TACH",IF(AND(C21>0,KL="Finalizado"),"Pendência de TACH",IF(AND(C21>0,KL="Não Criado"),"Pendência de TACH",IF(AND(C21>0,KL="Rascunho"),"Pendência de TACH",IF(AND(C21>0,L21="NECESSÁRIO AJUSTAR"),"Pendência de TACH",IF(AND(C21>0,L21="Aguardando Aprovação"),"Sem Pendência de TACH",IF(AND(C21>0,L21="Aprovado"),"Sem Pendência de TACH"))))))))))))))))))))))))} -> Pendência de TACH
A22: 4717 | B22: LUIZ ALBERTO BLANCHET | C22: 28 | D22: 0 | E22: CAMPUS CURITIBA | F22: 4093 - Direito - Adm - CTBA (Graduação Presencial) | G22: NÃO | H22: FINALIZADO | I22: FINALIZADO | J22: FINALIZADO | K22: FINALIZADO | L22: APROVADO | M22: =IF(AND(G22="SIM",D22>0),"Pendência de Agenda",IF(AND(G22="NÃO",D22=0),"Sem Pendência",IF(AND(G22="Sim",D22=0),"Sem Pendência",""))) -> Sem Pendência | N22: {=IF(AND(C22>0,I22="Finalizado"),"Pendência de TACH",IF(AND(C22>0,I22="Não Criado"),"Pendência de TACH",IF(AND(C22>0,I22="Rascunho"),"Pendência de TACH",IF(AND(C22>0,I22="NECESSÁRIO AJUSTAR"),"Pendência de TACH",IF(AND(C22>0,I22="Aguardando Aprovação"),"Sem Pendência de TACH",IF(AND(C22>0,I22="Aprovado"),"Sem Pendência de TACH",IF(AND(C22>0,J22="Finalizado"),"Pendência de TACH",IF(AND(C22>0,J22="Não Criado"),"Pendência de TACH",IF(AND(C22>0,J22="Rascunho"),"Pendência de TACH",IF(AND(C22>0,J22="NECESSÁRIO AJUSTAR"),"Pendência de TACH",IF(AND(C22>0,J22="Aguardando Aprovação"),"Sem Pendência de TACH",IF(AND(C22>0,J22="Aprovado"),"Sem Pendência de TACH",IF(AND(C22>0,K22="Finalizado"),"Pendência de TACH",IF(AND(C22>0,K22="Não Criado"),"Pendência de TACH",IF(AND(C22>0,K22="Rascunho"),"Pendência de TACH",IF(AND(C22>0,K22="NECESSÁRIO AJUSTAR"),"Pendência de TACH",IF(AND(C22>0,K22="Aguardando Aprovação"),"Sem Pendência de TACH",IF(AND(C22>0,K22="Aprovado"),"Sem Pendência de TACH",IF(AND(C22>0,KL="Finalizado"),"Pendência de TACH",IF(AND(C22>0,KL="Não Criado"),"Pendência de TACH",IF(AND(C22>0,KL="Rascunho"),"Pendência de TACH",IF(AND(C22>0,L22="NECESSÁRIO AJUSTAR"),"Pendência de TACH",IF(AND(C22>0,L22="Aguardando Aprovação"),"Sem Pendência de TACH",IF(AND(C22>0,L22="Aprovado"),"Sem Pendência de TACH"))))))))))))))))))))))))} -> Pendência de TACH
N23: {=IF(AND(C23>0,I23="Finalizado"),"Pendência de TACH",IF(AND(C23>0,I23="Não Criado"),"Pendência de TACH",IF(AND(C23>0,I23="Rascunho"),"Pendência de TACH",IF(AND(C23>0,I23="NECESSÁRIO AJUSTAR"),"Pendência de TACH",IF(AND(C23>0,I23="Aguardando Aprovação"),"Sem Pendência de TACH",IF(AND(C23>0,I23="Aprovado"),"Sem Pendência de TACH",IF(AND(C23>0,J23="Finalizado"),"Pendência de TACH",IF(AND(C23>0,J23="Não Criado"),"Pendência de TACH",IF(AND(C23>0,J23="Rascunho"),"Pendência de TACH",IF(AND(C23>0,J23="NECESSÁRIO AJUSTAR"),"Pendência de TACH",IF(AND(C23>0,J23="Aguardando Aprovação"),"Sem Pendência de TACH",IF(AND(C23>0,J23="Aprovado"),"Sem Pendência de TACH",IF(AND(C23>0,K23="Finalizado"),"Pendência de TACH",IF(AND(C23>0,K23="Não Criado"),"Pendência de TACH",IF(AND(C23>0,K23="Rascunho"),"Pendência de TACH",IF(AND(C23>0,K23="NECESSÁRIO AJUSTAR"),"Pendência de TACH",IF(AND(C23>0,K23="Aguardando Aprovação"),"Sem Pendência de TACH",IF(AND(C23>0,K23="Aprovado"),"Sem Pendência de TACH",IF(AND(C23>0,KL="Finalizado"),"Pendência de TACH",IF(AND(C23>0,KL="Não Criado"),"Pendência de TACH",IF(AND(C23>0,KL="Rascunho"),"Pendência de TACH",IF(AND(C23>0,L23="NECESSÁRIO AJUSTAR"),"Pendência de TACH",IF(AND(C23>0,L23="Aguardando Aprovação"),"Sem Pendência de TACH",IF(AND(C23>0,L23="Aprovado"),"Sem Pendência de TACH"))))))))))))))))))))))))} -> #NAME?
N24: {=IF(AND(C24>0,I24="Finalizado"),"Pendência de TACH",IF(AND(C24>0,I24="Não Criado"),"Pendência de TACH",IF(AND(C24>0,I24="Rascunho"),"Pendência de TACH",IF(AND(C24>0,I24="NECESSÁRIO AJUSTAR"),"Pendência de TACH",IF(AND(C24>0,I24="Aguardando Aprovação"),"Sem Pendência de TACH",IF(AND(C24>0,I24="Aprovado"),"Sem Pendência de TACH",IF(AND(C24>0,J24="Finalizado"),"Pendência de TACH",IF(AND(C24>0,J24="Não Criado"),"Pendência de TACH",IF(AND(C24>0,J24="Rascunho"),"Pendência de TACH",IF(AND(C24>0,J24="NECESSÁRIO AJUSTAR"),"Pendência de TACH",IF(AND(C24>0,J24="Aguardando Aprovação"),"Sem Pendência de TACH",IF(AND(C24>0,J24="Aprovado"),"Sem Pendência de TACH",IF(AND(C24>0,K24="Finalizado"),"Pendência de TACH",IF(AND(C24>0,K24="Não Criado"),"Pendência de TACH",IF(AND(C24>0,K24="Rascunho"),"Pendência de TACH",IF(AND(C24>0,K24="NECESSÁRIO AJUSTAR"),"Pendência de TACH",IF(AND(C24>0,K24="Aguardando Aprovação"),"Sem Pendência de TACH",IF(AND(C24>0,K24="Aprovado"),"Sem Pendência de TACH",IF(AND(C24>0,KL="Finalizado"),"Pendência de TACH",IF(AND(C24>0,KL="Não Criado"),"Pendência de TACH",IF(AND(C24>0,KL="Rascunho"),"Pendência de TACH",IF(AND(C24>0,L24="NECESSÁRIO AJUSTAR"),"Pendência de TACH",IF(AND(C24>0,L24="Aguardando Aprovação"),"Sem Pendência de TACH",IF(AND(C24>0,L24="Aprovado"),"Sem Pendência de TACH"))))))))))))))))))))))))} -> #NAME?
N25: {=IF(AND(C25>0,I25="Finalizado"),"Pendência de TACH",IF(AND(C25>0,I25="Não Criado"),"Pendência de TACH",IF(AND(C25>0,I25="Rascunho"),"Pendência de TACH",IF(AND(C25>0,I25="NECESSÁRIO AJUSTAR"),"Pendência de TACH",IF(AND(C25>0,I25="Aguardando Aprovação"),"Sem Pendência de TACH",IF(AND(C25>0,I25="Aprovado"),"Sem Pendência de TACH",IF(AND(C25>0,J25="Finalizado"),"Pendência de TACH",IF(AND(C25>0,J25="Não Criado"),"Pendência de TACH",IF(AND(C25>0,J25="Rascunho"),"Pendência de TACH",IF(AND(C25>0,J25="NECESSÁRIO AJUSTAR"),"Pendência de TACH",IF(AND(C25>0,J25="Aguardando Aprovação"),"Sem Pendência de TACH",IF(AND(C25>0,J25="Aprovado"),"Sem Pendência de TACH",IF(AND(C25>0,K25="Finalizado"),"Pendência de TACH",IF(AND(C25>0,K25="Não Criado"),"Pendência de TACH",IF(AND(C25>0,K25="Rascunho"),"Pendência de TACH",IF(AND(C25>0,K25="NECESSÁRIO AJUSTAR"),"Pendência de TACH",IF(AND(C25>0,K25="Aguardando Aprovação"),"Sem Pendência de TACH",IF(AND(C25>0,K25="Aprovado"),"Sem Pendência de TACH",IF(AND(C25>0,KL="Finalizado"),"Pendência de TACH",IF(AND(C25>0,KL="Não Criado"),"Pendência de TACH",IF(AND(C25>0,KL="Rascunho"),"Pendência de TACH",IF(AND(C25>0,L25="NECESSÁRIO AJUSTAR"),"Pendência de TACH",IF(AND(C25>0,L25="Aguardando Aprovação"),"Sem Pendência de TACH",IF(AND(C25>0,L25="Aprovado"),"Sem Pendência de TACH"))))))))))))))))))))))))} -> #NAME?
N26: {=IF(AND(C26>0,I26="Finalizado"),"Pendência de TACH",IF(AND(C26>0,I26="Não Criado"),"Pendência de TACH",IF(AND(C26>0,I26="Rascunho"),"Pendência de TACH",IF(AND(C26>0,I26="NECESSÁRIO AJUSTAR"),"Pendência de TACH",IF(AND(C26>0,I26="Aguardando Aprovação"),"Sem Pendência de TACH",IF(AND(C26>0,I26="Aprovado"),"Sem Pendência de TACH",IF(AND(C26>0,J26="Finalizado"),"Pendência de TACH",IF(AND(C26>0,J26="Não Criado"),"Pendência de TACH",IF(AND(C26>0,J26="Rascunho"),"Pendência de TACH",IF(AND(C26>0,J26="NECESSÁRIO AJUSTAR"),"Pendência de TACH",IF(AND(C26>0,J26="Aguardando Aprovação"),"Sem Pendência de TACH",IF(AND(C26>0,J26="Aprovado"),"Sem Pendência de TACH",IF(AND(C26>0,K26="Finalizado"),"Pendência de TACH",IF(AND(C26>0,K26="Não Criado"),"Pendência de TACH",IF(AND(C26>0,K26="Rascunho"),"Pendência de TACH",IF(AND(C26>0,K26="NECESSÁRIO AJUSTAR"),"Pendência de TACH",IF(AND(C26>0,K26="Aguardando Aprovação"),"Sem Pendência de TACH",IF(AND(C26>0,K26="Aprovado"),"Sem Pendência de TACH",IF(AND(C26>0,KL="Finalizado"),"Pendência de TACH",IF(AND(C26>0,KL="Não Criado"),"Pendência de TACH",IF(AND(C26>0,KL="Rascunho"),"Pendência de TACH",IF(AND(C26>0,L26="NECESSÁRIO AJUSTAR"),"Pendência de TACH",IF(AND(C26>0,L26="Aguardando Aprovação"),"Sem Pendência de TACH",IF(AND(C26>0,L26="Aprovado"),"Sem Pendência de TACH"))))))))))))))))))))))))} -> #NAME?
N27: {=IF(AND(C27>0,I27="Finalizado"),"Pendência de TACH",IF(AND(C27>0,I27="Não Criado"),"Pendência de TACH",IF(AND(C27>0,I27="Rascunho"),"Pendência de TACH",IF(AND(C27>0,I27="NECESSÁRIO AJUSTAR"),"Pendência de TACH",IF(AND(C27>0,I27="Aguardando Aprovação"),"Sem Pendência de TACH",IF(AND(C27>0,I27="Aprovado"),"Sem Pendência de TACH",IF(AND(C27>0,J27="Finalizado"),"Pendência de TACH",IF(AND(C27>0,J27="Não Criado"),"Pendência de TACH",IF(AND(C27>0,J27="Rascunho"),"Pendência de TACH",IF(AND(C27>0,J27="NECESSÁRIO AJUSTAR"),"Pendência de TACH",IF(AND(C27>0,J27="Aguardando Aprovação"),"Sem Pendência de TACH",IF(AND(C27>0,J27="Aprovado"),"Sem Pendência de TACH",IF(AND(C27>0,K27="Finalizado"),"Pendência de TACH",IF(AND(C27>0,K27="Não Criado"),"Pendência de TACH",IF(AND(C27>0,K27="Rascunho"),"Pendência de TACH",IF(AND(C27>0,K27="NECESSÁRIO AJUSTAR"),"Pendência de TACH",IF(AND(C27>0,K27="Aguardando Aprovação"),"Sem Pendência de TACH",IF(AND(C27>0,K27="Aprovado"),"Sem Pendência de TACH",IF(AND(C27>0,KL="Finalizado"),"Pendência de TACH",IF(AND(C27>0,KL="Não Criado"),"Pendência de TACH",IF(AND(C27>0,KL="Rascunho"),"Pendência de TACH",IF(AND(C27>0,L27="NECESSÁRIO AJUSTAR"),"Pendência de TACH",IF(AND(C27>0,L27="Aguardando Aprovação"),"Sem Pendência de TACH",IF(AND(C27>0,L27="Aprovado"),"Sem Pendência de TACH"))))))))))))))))))))))))} -> #NAME?
N28: {=IF(AND(C28>0,I28="Finalizado"),"Pendência de TACH",IF(AND(C28>0,I28="Não Criado"),"Pendência de TACH",IF(AND(C28>0,I28="Rascunho"),"Pendência de TACH",IF(AND(C28>0,I28="NECESSÁRIO AJUSTAR"),"Pendência de TACH",IF(AND(C28>0,I28="Aguardando Aprovação"),"Sem Pendência de TACH",IF(AND(C28>0,I28="Aprovado"),"Sem Pendência de TACH",IF(AND(C28>0,J28="Finalizado"),"Pendência de TACH",IF(AND(C28>0,J28="Não Criado"),"Pendência de TACH",IF(AND(C28>0,J28="Rascunho"),"Pendência de TACH",IF(AND(C28>0,J28="NECESSÁRIO AJUSTAR"),"Pendência de TACH",IF(AND(C28>0,J28="Aguardando Aprovação"),"Sem Pendência de TACH",IF(AND(C28>0,J28="Aprovado"),"Sem Pendência de TACH",IF(AND(C28>0,K28="Finalizado"),"Pendência de TACH",IF(AND(C28>0,K28="Não Criado"),"Pendência de TACH",IF(AND(C28>0,K28="Rascunho"),"Pendência de TACH",IF(AND(C28>0,K28="NECESSÁRIO AJUSTAR"),"Pendência de TACH",IF(AND(C28>0,K28="Aguardando Aprovação"),"Sem Pendência de TACH",IF(AND(C28>0,K28="Aprovado"),"Sem Pendência de TACH",IF(AND(C28>0,KL="Finalizado"),"Pendência de TACH",IF(AND(C28>0,KL="Não Criado"),"Pendência de TACH",IF(AND(C28>0,KL="Rascunho"),"Pendência de TACH",IF(AND(C28>0,L28="NECESSÁRIO AJUSTAR"),"Pendência de TACH",IF(AND(C28>0,L28="Aguardando Aprovação"),"Sem Pendência de TACH",IF(AND(C28>0,L28="Aprovado"),"Sem Pendência de TACH"))))))))))))))))))))))))} -> #NAME?
N29: {=IF(AND(C29>0,I29="Finalizado"),"Pendência de TACH",IF(AND(C29>0,I29="Não Criado"),"Pendência de TACH",IF(AND(C29>0,I29="Rascunho"),"Pendência de TACH",IF(AND(C29>0,I29="NECESSÁRIO AJUSTAR"),"Pendência de TACH",IF(AND(C29>0,I29="Aguardando Aprovação"),"Sem Pendência de TACH",IF(AND(C29>0,I29="Aprovado"),"Sem Pendência de TACH",IF(AND(C29>0,J29="Finalizado"),"Pendência de TACH",IF(AND(C29>0,J29="Não Criado"),"Pendência de TACH",IF(AND(C29>0,J29="Rascunho"),"Pendência de TACH",IF(AND(C29>0,J29="NECESSÁRIO AJUSTAR"),"Pendência de TACH",IF(AND(C29>0,J29="Aguardando Aprovação"),"Sem Pendência de TACH",IF(AND(C29>0,J29="Aprovado"),"Sem Pendência de TACH",IF(AND(C29>0,K29="Finalizado"),"Pendência de TACH",IF(AND(C29>0,K29="Não Criado"),"Pendência de TACH",IF(AND(C29>0,K29="Rascunho"),"Pendência de TACH",IF(AND(C29>0,K29="NECESSÁRIO AJUSTAR"),"Pendência de TACH",IF(AND(C29>0,K29="Aguardando Aprovação"),"Sem Pendência de TACH",IF(AND(C29>0,K29="Aprovado"),"Sem Pendência de TACH",IF(AND(C29>0,KL="Finalizado"),"Pendência de TACH",IF(AND(C29>0,KL="Não Criado"),"Pendência de TACH",IF(AND(C29>0,KL="Rascunho"),"Pendência de TACH",IF(AND(C29>0,L29="NECESSÁRIO AJUSTAR"),"Pendência de TACH",IF(AND(C29>0,L29="Aguardando Aprovação"),"Sem Pendência de TACH",IF(AND(C29>0,L29="Aprovado"),"Sem Pendência de TACH"))))))))))))))))))))))))} -> #NAME?
